<?xml version="1.0"?>

<robot name="robot" xmlns:xacro="http://www.ros.org/wiki/xacro">


  <!-- Color of materials -->
  <material name="yellow">
    <color rgba="1 1 0 1"/>
  </material>
  <material name="blue">
    <color rgba="0 0 1 1"/>
  </material>
  <material name="red">
    <color rgba="1 0 0 1"/>
  </material>
  <material name="grey">
    <color rgba="0.75 0.75 0.75 1"/>
  </material>
  <material name="mesa">
    <color rgba="0.53 0.41 0.28 1"/>
  </material>

   
<link name="right_leg">
  <visual>
    <geometry>
      <box size="0.6 0.3 0.5"/>
    </geometry>
    <origin rpy="0 0 0" xyz="0 0 0.25"/> 
    <material name= "mesa"/>
</visual>
</link>

<joint name="joint0" type="fixed">
  <parent link="right_leg"/>
  <child link="base_link"/>
</joint> 

 <link name="base_link">
    <visual>
     <geometry>
       <mesh filename="package://dishap/meshes1/Base2.stl" scale="0.001 0.001 0.001"/>   
     </geometry>
     <origin rpy="1.5708 0 1.5708" xyz="0 0 0.6775"/>  <!-- rpy= 0 0 0.1775" -->
     <material name="grey" /> 
    </visual>

    <collision>
     <geometry>
       <mesh filename="package://dishap/meshes1/Base2.stl" scale="0.001 0.001 0.001"/>   
     </geometry>
     <origin rpy="1.5708 0 1.5708" xyz="0 0 0.6775"/> 
    </collision>

    <inertial> 
      <mass value="4" />
      <inertia ixx="1.0" ixy="0.0" ixz="0.0" 
               iyy="1.0" iyz="0.0" izz="1.0" /> 
    </inertial>

  </link>
  <gazebo reference= "base_link">
    <material>Gazebo/Gray</material>
  </gazebo>


  <joint name="joint1" type="revolute">
    <parent link="base_link"/>
    <child link="link1"/>
    <origin xyz="0 0 0.6775"/>
    <axis xyz="0 0 1" />
    <limit effort="300" velocity="0.1" lower="-3.1" upper="3.1"/>
  </joint>


  <link name="link1">
    <visual>
    <geometry>
       <mesh filename="package://dishap/meshes1/Link1.stl" scale="0.001 0.001 0.001"/>   
    </geometry>
    <origin rpy="1.5708  0 1.5708" xyz="0 0 -0.0225"/>    <!-- rpy= "1.5708 0 0"-->
    <material name="blue" />
    </visual>

    <collision>
     <geometry>
       <mesh filename="package://dishap/meshes1/Link1.stl" scale="0.001 0.001 0.001"/>   
     </geometry>
     <origin rpy="1.5708 0 1.5708" xyz="0 0 -0.0225"/> 
    </collision>

    <inertial> 
      <mass value="0.1" />
      <inertia ixx="1.0" ixy="0.0" ixz="0.0" 
               iyy="1.0" iyz="0.0" izz="1.0" /> 
    </inertial>
  </link>
  <gazebo reference= "link1">
    <material>Gazebo/White</material>
  </gazebo>


  <joint name="joint2" type="revolute">
    <parent link="link1" />
    <child link="link2_3"  />
    <origin xyz="0 0.1  0"/>
    <axis xyz="-1 0 0" />
    <limit effort="300" velocity="0.1" lower="-3.1" upper="3.1"/>
  </joint>


  <link name="link2_3">
    <visual>
    <geometry>
       <mesh filename="package://dishap/meshes1/Link2_3.stl" scale="0.001 0.001 0.001"/>   
    </geometry>
    <origin rpy="1.5708 0  0" xyz="-0.0225 0 0"/>  <!-- rpy= "1.5708 0  -1.5708" -->
    <material name="grey" /> 
    </visual>

    <collision>
     <geometry>
       <mesh filename="package://dishap/meshes1/Link2_3.stl" scale="0.001 0.001 0.001"/>   
     </geometry>
     <origin rpy="1.5708 0 0" xyz="-0.0225 0 0"/> 
    </collision>

    <inertial> 
      <mass value="0.1" />
      <inertia ixx="1.0" ixy="0.0" ixz="0.0" 
               iyy="1.0" iyz="0.0" izz="1.0" />
    </inertial>
  </link>
  <gazebo reference= "link2_3">
    <material>Gazebo/White</material>
  </gazebo>


  <joint name="joint3" type="revolute">
    <parent link="link2_3" />
    <child link="link4"  />
    <origin xyz="0 0.0775 0.15"/>  <!-- 0.1275  -->
    <axis xyz="0 0 1" />
    <limit effort="300" velocity="0.1" lower="-3.1" upper="3.1"/>
  </joint>


  <link name="link4">
    <visual>
    <geometry>
       <mesh filename="package://dishap/meshes1/Link4.stl" scale="0.001 0.001 0.001"/>   
    </geometry>
    <origin rpy="1.5708 0 0" xyz="0 0 -0.0225"/>    <!-- rpy= "1.5708 0  -1.5708" -->
    <material name="blue" />
    </visual>

    <collision>
     <geometry>
       <mesh filename="package://dishap/meshes1/Link4.stl" scale="0.001 0.001 0.001"/>   
     </geometry>
     <origin rpy="1.5708 0 0" xyz="0 0 -0.0225"/> 
    </collision>

    <inertial> 
      <mass value="0.1" />
      <inertia ixx="1.0" ixy="0.0" ixz="0.0" 
               iyy="1.0" iyz="0.0" izz="1.0" />
    </inertial>
  </link>
  <gazebo reference= "link4">
    <material>Gazebo/White</material>
  </gazebo>


  <joint name="joint4" type="revolute">
    <parent link="link4" />
    <child link="link5_6"  />
    <origin xyz="0 0.1225  0"/> <!-- 0.1 -->
    <axis xyz="0 1 0" />
    <limit effort="300" velocity="0.1" lower="-3.1" upper="3.1"/>
  </joint>


  <link name="link5_6">
    <visual>
    <geometry>
       <mesh filename="package://dishap/meshes1/Link5_6.stl" scale="0.001 0.001 0.001"/>   
    </geometry>
    <origin rpy="1.5708 0 0" xyz="0 0.0225 0"/>  <!-- rpy= "1.5708 0  -1.5708" -->
    <material name="grey" />
    </visual>

    <collision>
     <geometry>
       <mesh filename="package://dishap/meshes1/Link5_6.stl" scale="0.001 0.001 0.001"/>  
     </geometry>
     <origin rpy="1.5708 0 0" xyz="0 0.0225 0"/> 
    </collision>

    <inertial> 
      <mass value="0.1" />
      <inertia ixx="1.0" ixy="0.0" ixz="0.0" 
               iyy="1.0" iyz="0.0" izz="1.0" />
    </inertial>
  </link>
  <gazebo reference= "link5_6">
    <material>Gazebo/White</material>
  </gazebo>


  <joint name="joint5" type="revolute">
    <parent link="link5_6" />
    <child link="link7"  />
    <origin xyz="0 0.1 -0.0775"/> <!-- y 0.1225 -->
    <axis xyz="0 1 0" />
    <limit effort="300" velocity="0.1" lower="-3.1" upper="3.1"/>
  </joint>

  <link name="link7">
    <visual>
    <geometry>
       <mesh filename="package://dishap/meshes1/Link7.stl" scale="0.001 0.001 0.001"/>   
    </geometry>
    <origin rpy="1.5708 0 3.1416" xyz="0 -0.0225 0"/>  <!-- rpy= "1.5708 0  1.5708" -->
    <material name="blue" />
    </visual>

    <collision>
     <geometry>
       <mesh filename="package://dishap/meshes1/Link7.stl" scale="0.001 0.001 0.001"/>   
     </geometry>
     <origin rpy="1.5708 0 3.1416" xyz="0 -0.0225 0"/> 
    </collision>

    <inertial> 
      <mass value="0.1" />
      <inertia ixx="1.0" ixy="0.0" ixz="0.0" 
               iyy="1.0" iyz="0.0" izz="1.0" />
    </inertial>  
  </link>
  <gazebo reference= "link7">
    <material>Gazebo/White</material>
  </gazebo>


  <joint name="joint6" type="revolute">
    <parent link="link7" />
    <child link="link8"  />
    <origin xyz="0 0  -0.1225"/>   <!-- -0.1 -->
    <axis xyz="0 0 -1" />
    <limit effort="300" velocity="0.1" lower="-3.1" upper="3.1"/>
  </joint>


  <link name="link8">
    <visual>
    <geometry>
       <mesh filename="package://dishap/meshes1/Link8.stl" scale="0.001 0.001 0.001"/>   
    </geometry>
    <origin rpy="1.5708 0 1.5708" xyz="0 0 -0.0225"/>  <!-- rpy= "1.5708 0  0" -->
    <material name="grey" />
    </visual>

    <collision>    
     <geometry>
       <mesh filename="package://dishap/meshes1/Link8.stl" scale="0.001 0.001 0.001"/>   
     </geometry>
     <origin rpy="1.5708 0 1.5708" xyz="0 0 -0.0225"/>  
    </collision>

    <inertial> 
      <mass value="0.1" />
      <inertia ixx="1.0" ixy="0.0" ixz="0.0" 
               iyy="1.0" iyz="0.0" izz="1.0" />
    </inertial> 
  </link>
  <gazebo reference= "link8">
    <material>Gazebo/White</material>
  </gazebo>

  <joint name="joint7" type="revolute">
    <parent link="link8" />
    <child link="link9"  />
    <origin xyz="0 0.1225 0"/>  <!-- 0.1 -->
    <axis xyz="0 1 0" />
    <limit effort="300" velocity="0.1" lower="-3.1" upper="3.1"/>
  </joint>

  <link name="link9">
    <visual>
    <geometry>
       <mesh filename="package://dishap/meshes1/Link9.stl" scale="0.001 0.001 0.001"/>   
    </geometry>
    <origin rpy="-1.5708 3.1416 0" xyz="0 0 0"/>  <!-- rpy= "1.5708 0  0" -->
    <material name="blue" />
    </visual>

    <collision>    
     <geometry>
       <mesh filename="package://dishap/meshes1/Link8.stl" scale="0.001 0.001 0.001"/>   
     </geometry>
     <origin rpy="-1.5708 3.1416 0" xyz="0 0 -0.0225"/>  
    </collision>

    <inertial> 
      <mass value="0.1" />
      <inertia ixx="1.0" ixy="0.0" ixz="0.0" 
               iyy="1.0" iyz="0.0" izz="1.0" />
    </inertial> 

  </link>
  <gazebo reference= "link9">
    <material>Gazebo/White</material>
  </gazebo>


<gazebo>
  <plugin name="gazebo_ros_control" filename="libgazebo_ros_control.so">
    <robotNamespace>/robot</robotNamespace>
    <legacyModeNS>true</legacyModeNS>
  </plugin>
</gazebo>

</robot>