<?xml version="1.0"?>

<robot name="robot">


  <!-- Color of materials -->
  <material name="yellow">
    <color rgba="1 1 0 1"/>
  </material>
  <material name="blue">
    <color rgba="0 0 1 1"/>
  </material>
  <material name="red">
    <color rgba="1 0 0 1"/>
  </material>
  <material name="grey">
    <color rgba="0.75 0.75 0.75 1"/>
  </material>

  <link name="right_leg">
    <visual>
      <geometry>
        <box size="0.6 0.3 0.5"/>
      </geometry>
      <origin rpy="0 0 0" xyz="0 0 0.25"/> 
    </visual>

    <collision>
      <geometry>
        <box size="0.6 0.3 0.5"/>
      </geometry>
      <origin rpy="0 0 0" xyz="0 0 0.25"/> 
    </collision>
    
    <inertial> 
      <mass value="10" /> <!-- kg -->
      <inertia ixx="1.0" ixy="0.0" ixz="0.0" 
               iyy="1.0" iyz="0.0" izz="1.0" /> 
    </inertial>
  </link>
  <gazebo reference= "right_leg">
    <material>Gazebo/Black</material>
  </gazebo>

  <joint name="joint0" type="fixed">
    <parent link="right_leg"/>
    <child link="base_link"/>
  </joint> 

  <link name="base_link">
    <visual>
     <geometry>
       <mesh filename="package://dishap/meshes1/Base2.stl" scale="0.001 0.001 0.001"/>   
     </geometry>
     <origin rpy="1.5708 0 1.5708" xyz="0 0 0.6775"/>  <!-- rpy= "1.5708 0 0"-->
     <material name="grey" /> 
    </visual>

    <collision>
     <geometry>
       <mesh filename="package://dishap/meshes1/Base2.stl" scale="0.001 0.001 0.001"/>   
     </geometry>
     <origin rpy="1.5708 0 1.5708" xyz="0 0 0.6775"/> 
    </collision>

    <inertial> 
      <mass value="10" /> <!-- kg -->
      <inertia ixx="1.0" ixy="0.0" ixz="0.0" 
               iyy="1.0" iyz="0.0" izz="1.0" /> 
    </inertial>
  </link>
  <gazebo reference= "base_link">
    <material>Gazebo/Gray</material>
  </gazebo>


  <joint name="joint1" type="revolute">
    <parent link="base_link"/>
    <child link="link1"/>
    <origin xyz="0 0  0.6775"/>
    <axis xyz="0 0 1" />
    <limit effort="300" velocity="0.1" lower="-3.1" upper="3.1"/>
  </joint>


  <link name="link1">
    <visual>
    <geometry>
       <mesh filename="package://dishap/meshes1/Link1.stl" scale="0.001 0.001 0.001"/>   
    </geometry>
    <origin rpy="1.5708  0 1.5708" xyz="0 0 -0.0225"/>    <!-- rpy= "1.5708 0 0"-->
    <material name="blue" />
    </visual>

    <collision>
     <geometry>
       <mesh filename="package://dishap/meshes1/Link1.stl" scale="0.001 0.001 0.001"/>   
     </geometry>
     <origin rpy="1.5708 0 1.5708" xyz="0 0 -0.0225"/> 
    </collision>

    <inertial> 
      <mass value="0.1" />
      <inertia ixx="1.0" ixy="0.0" ixz="0.0" 
               iyy="1.0" iyz="0.0" izz="1.0" /> 
    </inertial>
  </link>
  <gazebo reference= "link1">
    <material>Gazebo/White</material>
  </gazebo>


  <joint name="joint2" type="revolute">
    <parent link="link1" />
    <child link="link2_3"  />
    <origin xyz="0 0.1  0"/>
    <axis xyz="-1 0 0" />
    <limit effort="300" velocity="0.1" lower="-3.1" upper="3.1"/>
  </joint>


  <link name="link2_3">
    <visual>
    <geometry>
       <mesh filename="package://dishap/meshes1/Link2_3.stl" scale="0.001 0.001 0.001"/>   
    </geometry>
    <origin rpy="1.5708 0  0" xyz="-0.0225 0 0"/>  <!-- rpy= "1.5708 0  -1.5708" -->
    <material name="grey" /> 
    </visual>

    <collision>
     <geometry>
       <mesh filename="package://dishap/meshes1/Link2_3.stl" scale="0.001 0.001 0.001"/>   
     </geometry>
     <origin rpy="1.5708 0 0" xyz="-0.0225 0 0"/> 
    </collision>

    <inertial> 
      <mass value="0.1" />
      <inertia ixx="1.0" ixy="0.0" ixz="0.0" 
               iyy="1.0" iyz="0.0" izz="1.0" />
    </inertial>
  </link>
  <gazebo reference= "link2_3">
    <material>Gazebo/Gray</material>
  </gazebo>


  <joint name="joint3" type="revolute">
    <parent link="link2_3" />
    <child link="link4"  />
    <origin xyz="0 0.0775 0.15"/>
    <axis xyz="0 0 1" />
    <limit effort="300" velocity="0.1" lower="-3.1" upper="3.1"/>
  </joint>


  <link name="link4">
    <visual>
    <geometry>
       <mesh filename="package://dishap/meshes1/Link4.stl" scale="0.001 0.001 0.001"/>   
    </geometry>
    <origin rpy="1.5708 0 0" xyz="0 0 -0.0225"/>    <!-- rpy= "1.5708 0  -1.5708" -->
    <material name="blue" />
    </visual>

    <collision>
     <geometry>
       <mesh filename="package://dishap/meshes1/Link4.stl" scale="0.001 0.001 0.001"/>   
     </geometry>
     <origin rpy="1.5708 0 0" xyz="0 0 -0.0225"/> 
    </collision>

    <inertial> 
      <mass value="0.1" />
      <inertia ixx="1.0" ixy="0.0" ixz="0.0" 
               iyy="1.0" iyz="0.0" izz="1.0" />
    </inertial>
  </link>
  <gazebo reference= "link4">
    <material>Gazebo/White</material>
  </gazebo>


  <joint name="joint4" type="revolute">
    <parent link="link4" />
    <child link="link5_6"  />
    <origin xyz="0 0.1225  0"/>
    <axis xyz="0 1 0" />
    <limit effort="300" velocity="0.1" lower="-3.1" upper="3.1"/>
  </joint>


  <link name="link5_6">
    <visual>
    <geometry>
       <mesh filename="package://dishap/meshes1/Link5_6.stl" scale="0.001 0.001 0.001"/>   
    </geometry>
    <origin rpy="1.5708 0 0" xyz="0 0.0225 0"/>  <!-- rpy= "1.5708 0  -1.5708" -->
    <material name="grey" />
    </visual>

    <collision>
     <geometry>
       <mesh filename="package://dishap/meshes1/Link5_6.stl" scale="0.001 0.001 0.001"/>  
     </geometry>
     <origin rpy="1.5708 0 0" xyz="0 0.0225 0"/> 
    </collision>

    <inertial> 
      <mass value="0.1" />
      <inertia ixx="1.0" ixy="0.0" ixz="0.0" 
               iyy="1.0" iyz="0.0" izz="1.0" />
    </inertial>
  </link>
  <gazebo reference= "link5_6">
    <material>Gazebo/Gray</material>
  </gazebo>


  <joint name="joint5" type="revolute">
    <parent link="link5_6" />
    <child link="link7"  />
    <origin xyz="0 0.1 -0.0775"/>
    <axis xyz="0 1 0" />
    <limit effort="300" velocity="0.1" lower="-3.1" upper="3.1"/>
  </joint>

  <link name="link7">
    <visual>
    <geometry>
       <mesh filename="package://dishap/meshes1/Link7.stl" scale="0.001 0.001 0.001"/>   
    </geometry>
    <origin rpy="1.5708 0 3.1416" xyz="0 -0.0225 0"/>  <!-- rpy= "1.5708 0  1.5708" -->
    <material name="blue" />
    </visual>

    <collision>
     <geometry>
       <mesh filename="package://dishap/meshes1/Link7.stl" scale="0.001 0.001 0.001"/>   
     </geometry>
     <origin rpy="1.5708 0 3.1416" xyz="0 -0.0225 0"/> 
    </collision>

    <inertial> 
      <mass value="0.1" />
      <inertia ixx="1.0" ixy="0.0" ixz="0.0" 
               iyy="1.0" iyz="0.0" izz="1.0" />
    </inertial>  
  </link>
  <gazebo reference= "link7">
    <material>Gazebo/White</material>
  </gazebo>


  <joint name="joint6" type="revolute">
    <parent link="link7" />
    <child link="link8"  />
    <origin xyz="0 0  -0.1225"/>
    <axis xyz="0 0 -1" />
    <limit effort="300" velocity="0.1" lower="-3.1" upper="3.1"/>
  </joint>


  <link name="link8">
    <visual>
    <geometry>
       <mesh filename="package://dishap/meshes1/Link8.stl" scale="0.001 0.001 0.001"/>   
    </geometry>
    <origin rpy="1.5708 0 1.5708" xyz="0 0 -0.0225"/>  <!-- rpy= "1.5708 0  0" -->
    <material name="grey" />
    </visual>

    <collision>    
     <geometry>
       <mesh filename="package://dishap/meshes1/Link8.stl" scale="0.001 0.001 0.001"/>   
     </geometry>
     <origin rpy="1.5708 0 1.5708" xyz="0 0 -0.0225"/>  
    </collision>

    <inertial> 
      <mass value="0.1" />
      <inertia ixx="1.0" ixy="0.0" ixz="0.0" 
               iyy="1.0" iyz="0.0" izz="1.0" />
    </inertial> 
  </link>
  <gazebo reference= "link8">
    <material>Gazebo/Gray</material>
  </gazebo>

  <joint name="joint7" type="revolute">
    <parent link="link8" />
    <child link="link9"  />
    <origin xyz="0 0.1225 0"/>
    <axis xyz="0 1 0" />
    <limit effort="300" velocity="0.1" lower="-3.1" upper="3.1"/>
  </joint>

  <link name="link9">
    <visual>
    <geometry>
       <mesh filename="package://dishap/meshes1/Link9.stl" scale="0.001 0.001 0.001"/>   
    </geometry>
    <origin rpy="-1.5708 3.1416 0" xyz="0 0 0"/>  <!-- rpy= "1.5708 0  0" -->
    <material name="blue" />
    </visual>

    <collision>    
     <geometry>
       <mesh filename="package://dishap/meshes1/Link8.stl" scale="0.001 0.001 0.001"/>   
     </geometry>
     <origin rpy="-1.5708 3.1416 0" xyz="0 0 -0.0225"/>  
    </collision>

    <inertial> 
      <mass value="0.1" />
      <inertia ixx="1.0" ixy="0.0" ixz="0.0" 
               iyy="1.0" iyz="0.0" izz="1.0" />
    </inertial> 

  </link>

  <gazebo reference= "link9">
    <material>Gazebo/White</material>
  </gazebo>






  <!-- Transmission -->
  <transmission name="trans1">
    <type>transmission_interface/SimpleTransmission</type>
    <joint name="joint1">
      <hardwareInterface>hardware_interface/EffortJointInterface</hardwareInterface>
    </joint>
    <actuator name="motor1">
      <hardwareInterface>hardware_interface/EffortJointInterface</hardwareInterface>
      <mechanicalReduction>1</mechanicalReduction>
    </actuator>
  </transmission>

  <transmission name="trans2">
    <type>transmission_interface/SimpleTransmission</type>
    <joint name="joint2">
      <hardwareInterface>hardware_interface/EffortJointInterface</hardwareInterface>
    </joint>
    <actuator name="motor2">
      <hardwareInterface>hardware_interface/EffortJointInterface</hardwareInterface>
      <mechanicalReduction>1</mechanicalReduction>
    </actuator>
  </transmission>

  <transmission name="trans3">
    <type>transmission_interface/SimpleTransmission</type>
    <joint name="joint3">
      <hardwareInterface>hardware_interface/EffortJointInterface</hardwareInterface>
    </joint>
    <actuator name="motor3">
      <hardwareInterface>hardware_interface/EffortJointInterface</hardwareInterface>
      <mechanicalReduction>1</mechanicalReduction>
    </actuator>
  </transmission>

  <transmission name="trans4">
    <type>transmission_interface/SimpleTransmission</type>
    <joint name="joint4">
      <hardwareInterface>hardware_interface/EffortJointInterface</hardwareInterface>
    </joint>
    <actuator name="motor4">
      <hardwareInterface>hardware_interface/EffortJointInterface</hardwareInterface>
      <mechanicalReduction>1</mechanicalReduction>
    </actuator>
  </transmission>

  <transmission name="trans5">
    <type>transmission_interface/SimpleTransmission</type>
    <joint name="joint5">
      <hardwareInterface>hardware_interface/EffortJointInterface</hardwareInterface>
    </joint>
    <actuator name="motor5">
      <hardwareInterface>hardware_interface/EffortJointInterface</hardwareInterface>
      <mechanicalReduction>1</mechanicalReduction>
    </actuator>
  </transmission>

  <transmission name="trans6">
    <type>transmission_interface/SimpleTransmission</type>
    <joint name="joint6">
      <hardwareInterface>hardware_interface/EffortJointInterface</hardwareInterface>
    </joint>
    <actuator name="motor6">
      <hardwareInterface>hardware_interface/EffortJointInterface</hardwareInterface>
      <mechanicalReduction>1</mechanicalReduction>
    </actuator>
  </transmission>

  <transmission name="trans7">
    <type>transmission_interface/SimpleTransmission</type>
    <joint name="joint7">
      <hardwareInterface>hardware_interface/EffortJointInterface</hardwareInterface>
    </joint>
    <actuator name="motor7">
      <hardwareInterface>hardware_interface/EffortJointInterface</hardwareInterface>
      <mechanicalReduction>1</mechanicalReduction>
    </actuator>
  </transmission>

  <gazebo>
    <plugin name="gazebo_ros_control" filename="libgazebo_ros_control.so">
      <robotNamespace>/robot</robotNamespace>
      <legacyModeNS>true</legacyModeNS>
    </plugin>
  </gazebo>

</robot>